[2021-03-12 10:28:36] Request: 
data_source.open_dataset(time_range=('1978-11-01', '1978-11-02'), var_names=['freqbandID', 'dnflag'], region=None)

Traceback (most recent call last):
  File "/home/alicja/miniconda3/envs/cate-env/lib/python3.7/site-packages/xarray/backends/file_manager.py", line 199, in _acquire_with_cache_info
    file = self._cache[self._key]
  File "/home/alicja/miniconda3/envs/cate-env/lib/python3.7/site-packages/xarray/backends/lru_cache.py", line 53, in __getitem__
    value = self._cache[key]
KeyError: [<class 'netCDF4._netCDF4.Dataset'>, ('https://data.cci.ceda.ac.uk/thredds/dodsC/esacci/soil_moisture/data/daily_files/COMBINED/v05.2/1983/ESACCI-SOILMOISTURE-L3S-SSMV-COMBINED-19830118000000-fv05.2.nc#fillmismatch',), 'r', (('clobber', True), ('diskless', False), ('format', 'NETCDF4'), ('persist', False))]

During handling of the above exception, another exception occurred:

Traceback (most recent call last):
  File "/home/alicja/Desktop/projects/cate/cate/ds/esa_cci_odp.py", line 1250, in open_dataset
    return open_xarray_dataset(files, region=region, var_names=var_names, monitor=monitor)
  File "/home/alicja/Desktop/projects/cate/cate/core/ds.py", line 782, in open_xarray_dataset
    **kwargs)
  File "/home/alicja/miniconda3/envs/cate-env/lib/python3.7/site-packages/xarray/backends/api.py", line 948, in open_mfdataset
    datasets = [open_(p, **open_kwargs) for p in paths]
  File "/home/alicja/miniconda3/envs/cate-env/lib/python3.7/site-packages/xarray/backends/api.py", line 948, in <listcomp>
    datasets = [open_(p, **open_kwargs) for p in paths]
  File "/home/alicja/miniconda3/envs/cate-env/lib/python3.7/site-packages/xarray/backends/api.py", line 572, in open_dataset
    store = opener(filename_or_obj, **extra_kwargs, **backend_kwargs)
  File "/home/alicja/miniconda3/envs/cate-env/lib/python3.7/site-packages/xarray/backends/netCDF4_.py", line 364, in open
    return cls(manager, group=group, mode=mode, lock=lock, autoclose=autoclose)
  File "/home/alicja/miniconda3/envs/cate-env/lib/python3.7/site-packages/xarray/backends/netCDF4_.py", line 314, in __init__
    self.format = self.ds.data_model
  File "/home/alicja/miniconda3/envs/cate-env/lib/python3.7/site-packages/xarray/backends/netCDF4_.py", line 373, in ds
    return self._acquire()
  File "/home/alicja/miniconda3/envs/cate-env/lib/python3.7/site-packages/xarray/backends/netCDF4_.py", line 367, in _acquire
    with self._manager.acquire_context(needs_lock) as root:
  File "/home/alicja/miniconda3/envs/cate-env/lib/python3.7/contextlib.py", line 112, in __enter__
    return next(self.gen)
  File "/home/alicja/miniconda3/envs/cate-env/lib/python3.7/site-packages/xarray/backends/file_manager.py", line 187, in acquire_context
    file, cached = self._acquire_with_cache_info(needs_lock)
  File "/home/alicja/miniconda3/envs/cate-env/lib/python3.7/site-packages/xarray/backends/file_manager.py", line 205, in _acquire_with_cache_info
    file = self._opener(*self._args, **kwargs)
  File "netCDF4/_netCDF4.pyx", line 2291, in netCDF4._netCDF4.Dataset.__init__
  File "netCDF4/_netCDF4.pyx", line 1855, in netCDF4._netCDF4._ensure_nc_success
OSError: [Errno -68] NetCDF: I/O failure: b'https://data.cci.ceda.ac.uk/thredds/dodsC/esacci/soil_moisture/data/daily_files/COMBINED/v05.2/1983/ESACCI-SOILMOISTURE-L3S-SSMV-COMBINED-19830118000000-fv05.2.nc#fillmismatch'

The above exception was the direct cause of the following exception:

Traceback (most recent call last):
  File "/home/alicja/Desktop/projects/cate-e2e/testing-cci-datasets/test_cci_data_support.py", line 282, in test_open_ds
    cube = data_source.open_dataset(time_range=time_range, var_names=var_list)
  File "/home/alicja/Desktop/projects/cate/cate/ds/esa_cci_odp.py", line 1259, in open_dataset
    cause=e) from e
cate.core.ds.DataAccessError: Failed to open data source "esacci.SOILMOISTURE.day.L3S.SSMV.multi-sensor.multi-platform.COMBINED.05-2.r1" for given time range, variable names: [Errno -68] NetCDF: I/O failure: b'https://data.cci.ceda.ac.uk/thredds/dodsC/esacci/soil_moisture/data/daily_files/COMBINED/v05.2/1983/ESACCI-SOILMOISTURE-L3S-SSMV-COMBINED-19830118000000-fv05.2.nc#fillmismatch'
