[2021-03-12 09:03:51] Request: 
data_source.open_dataset(time_range=('2002-06-01', '2002-06-03'), var_names=['xc', 'algorithm_standard_error'], region=[11.9, -37.5, 12.0, -37.4])

Traceback (most recent call last):
  File "/home/alicja/Desktop/projects/cate-e2e/testing-cci-datasets/test_cci_data_support.py", line 300, in test_open_ds
    cube = data_source.open_dataset(time_range=time_range, var_names=var_list, region=region)
  File "/home/alicja/Desktop/projects/cate/cate/ds/esa_cci_odp.py", line 1250, in open_dataset
    return open_xarray_dataset(files, region=region, var_names=var_names, monitor=monitor)
  File "/home/alicja/Desktop/projects/cate/cate/core/ds.py", line 790, in open_xarray_dataset
    ds = subset_spatial_impl(ds, region)
  File "/home/alicja/Desktop/projects/cate/cate/core/opimpl.py", line 898, in subset_spatial_impl
    raise ValidationError('Cannot apply regional subset. No (valid) geocoding found.')
cate.core.types.ValidationError: Cannot apply regional subset. No (valid) geocoding found.
