[2021-03-12 09:03:53] Request: 
data_source.open_dataset(time_range=('2009-06-01', '2009-06-02'), var_names=['solar_zenith_angle', 'xco2_quality_flag'], region=None)

Traceback (most recent call last):
  File "/home/alicja/Desktop/projects/cate-e2e/testing-cci-datasets/test_cci_data_support.py", line 282, in test_open_ds
    cube = data_source.open_dataset(time_range=time_range, var_names=var_list)
  File "/home/alicja/Desktop/projects/cate/cate/ds/esa_cci_odp.py", line 1250, in open_dataset
    return open_xarray_dataset(files, region=region, var_names=var_names, monitor=monitor)
  File "/home/alicja/Desktop/projects/cate/cate/core/ds.py", line 782, in open_xarray_dataset
    **kwargs)
  File "/home/alicja/miniconda3/envs/cate-env/lib/python3.7/site-packages/xarray/backends/api.py", line 982, in open_mfdataset
    combine_attrs="drop",
  File "/home/alicja/miniconda3/envs/cate-env/lib/python3.7/site-packages/xarray/core/combine.py", line 762, in combine_by_coords
    list(datasets_with_same_vars)
  File "/home/alicja/miniconda3/envs/cate-env/lib/python3.7/site-packages/xarray/core/combine.py", line 109, in _infer_concat_order_from_coords
    "Could not find any dimension coordinates to use to "
ValueError: Could not find any dimension coordinates to use to order the datasets for concatenation
