[2021-05-17 15:38:19] Request: 
open_dataset(ds_id=esacci.SST.day.L3C.SSTskin.AVHRR-2.NOAA-14.AVHRR14_G.2-1.day, store_id=cci-store, time_range=None, var_names=['adjustment_alt', 'sses_standard_deviation'], region=[9.02873, 89.91798, 9.12873, 90.01798])

Traceback (most recent call last):
  File "test_cci_data_support.py", line 395, in test_open_ds
    dataset = open_dataset(ds_id=data_id,
  File "/home/users/tfincke/Projects/cate/cate/core/op.py", line 216, in __call__
    return_value = self._wrapped_op(**input_values)
  File "/home/users/tfincke/Projects/cate/cate/ops/io.py", line 85, in open_dataset
    ds, ds_id = cate.core.ds.open_dataset(dataset_id=ds_id,
  File "/home/users/tfincke/Projects/cate/cate/core/ds.py", line 436, in open_dataset
    dataset = data_store.open_data(data_id=dataset_id, opener_id=opener_id, **open_args)
  File "/home/users/tfincke/Projects/xcube-cci/xcube_cci/dataaccess.py", line 476, in open_data
    return self._get_opener(opener_id=opener_id).open_data(data_id, **open_params)
  File "/home/users/tfincke/Projects/xcube-cci/xcube_cci/dataaccess.py", line 230, in open_data
    cci_schema.validate_instance(open_params)
  File "/home/users/tfincke/Projects/xcube/xcube/util/jsonschema.py", line 101, in validate_instance
    jsonschema.validate(instance=instance, schema=self.to_dict(),
  File "/home/users/tfincke/miniconda3/envs/xcube/lib/python3.8/site-packages/jsonschema/validators.py", line 934, in validate
    raise error
jsonschema.exceptions.ValidationError: 90.01798 is greater than the maximum of 90.0

Failed validating 'maximum' in schema['properties']['bbox']['items'][3]:
    {'maximum': 90.0, 'minimum': -90.0, 'type': 'number'}

On instance['bbox'][3]:
    90.01798
