[2021-12-21 12:19:39] Request: 
open_dataset(ds_id=ESACCI-GHG-L2-CH4-SCIAMACHY-WFMD-2002-2011-fv1.zarr, store_id=cci-zarr-store, time_range=None, var_names=['xch4_averaging_kernel', 'xch4_uncertainty'], region=[59.14412, 6.2333, 61.14412, 8.2333])

Traceback (most recent call last):
  File "/home/xcube/projects/cate-e2e/testing-cci-datasets/test_cci_data_support.py", line 428, in test_open_ds
    dataset = open_dataset(ds_id=data_id,
  File "/home/xcube/projects/cate/cate/core/op.py", line 216, in __call__
    return_value = self._wrapped_op(**input_values)
  File "/home/xcube/projects/cate/cate/ops/io.py", line 85, in open_dataset
    ds, ds_id = cate.core.ds.open_dataset(dataset_id=ds_id,
  File "/home/xcube/projects/cate/cate/core/ds.py", line 452, in open_dataset
    dataset = select_subset(dataset, **subset_args)
  File "/home/xcube/miniconda3/envs/cate-env-development/lib/python3.9/site-packages/xcube/core/select.py", line 64, in select_subset
    dataset = select_spatial_subset(dataset, xy_bbox=bbox)
  File "/home/xcube/miniconda3/envs/cate-env-development/lib/python3.9/site-packages/xcube/core/select.py", line 131, in select_spatial_subset
    grid_mapping = GridMapping.from_dataset(dataset,
  File "/home/xcube/miniconda3/envs/cate-env-development/lib/python3.9/site-packages/xcube/core/gridmapping/base.py", line 664, in from_dataset
    return new_grid_mapping_from_dataset(
  File "/home/xcube/miniconda3/envs/cate-env-development/lib/python3.9/site-packages/xcube/core/gridmapping/dataset.py", line 103, in new_grid_mapping_from_dataset
    raise ValueError('cannot find any grid mapping in dataset')
ValueError: cannot find any grid mapping in dataset
