[2021-05-27 15:38:04] Request: 
open_dataset(ds_id=esacci.GHG.satellite-orbit-frequency.L2.CO2.TANSO-FTS.GOSAT.SRFP.v2-3-8.r1, store_id=cci-store, time_range=None, var_names=['co2_profile_apriori', 'latitude'], region=[-73.20983, -10.42091, -52.20983, 10.57909])

Traceback (most recent call last):
  File "test_cci_data_support.py", line 404, in test_open_ds
    dataset = open_dataset(ds_id=data_id,
  File "/home/users/tfincke/Projects/cate/cate/core/op.py", line 216, in __call__
    return_value = self._wrapped_op(**input_values)
  File "/home/users/tfincke/Projects/cate/cate/ops/io.py", line 85, in open_dataset
    ds, ds_id = cate.core.ds.open_dataset(dataset_id=ds_id,
  File "/home/users/tfincke/Projects/cate/cate/core/ds.py", line 438, in open_dataset
    dataset = select_subset(dataset, **subset_args)
  File "/home/users/tfincke/Projects/xcube/xcube/core/select.py", line 37, in select_subset
    dataset = select_spatial_subset(dataset, xy_bbox=bbox)
  File "/home/users/tfincke/Projects/xcube/xcube/core/select.py", line 86, in select_spatial_subset
    x_name, y_name = get_dataset_xy_names(dataset, xy_names=xy_names)
  File "/home/users/tfincke/Projects/xcube/xcube/core/geocoding.py", line 437, in get_dataset_xy_names
    return (_get_coord_var_name(dataset, x_name, X_COORD_VAR_NAMES, 'x'),
  File "/home/users/tfincke/Projects/xcube/xcube/core/geocoding.py", line 447, in _get_coord_var_name
    raise ValueError(f'cannot detect {dim_name!r}-coordinate variable in dataset')
ValueError: cannot detect 'x'-coordinate variable in dataset
[2021-05-27 15:45:29] Request: 
open_dataset(ds_id=esacci.GHG.satellite-orbit-frequency.L2.CO2.TANSO-FTS.GOSAT.SRFP.v2-3-8.r1, store_id=cci-store, time_range=None, var_names=['x_wind', 'raw_xco2_err'], region=[69.76001, -46.97501, 90.76001, -25.97501])

Traceback (most recent call last):
  File "test_cci_data_support.py", line 404, in test_open_ds
    dataset = open_dataset(ds_id=data_id,
  File "/home/users/tfincke/Projects/cate/cate/core/op.py", line 216, in __call__
    return_value = self._wrapped_op(**input_values)
  File "/home/users/tfincke/Projects/cate/cate/ops/io.py", line 85, in open_dataset
    ds, ds_id = cate.core.ds.open_dataset(dataset_id=ds_id,
  File "/home/users/tfincke/Projects/cate/cate/core/ds.py", line 438, in open_dataset
    dataset = select_subset(dataset, **subset_args)
  File "/home/users/tfincke/Projects/xcube/xcube/core/select.py", line 37, in select_subset
    dataset = select_spatial_subset(dataset, xy_bbox=bbox)
  File "/home/users/tfincke/Projects/xcube/xcube/core/select.py", line 86, in select_spatial_subset
    x_name, y_name = get_dataset_xy_names(dataset, xy_names=xy_names)
  File "/home/users/tfincke/Projects/xcube/xcube/core/geocoding.py", line 437, in get_dataset_xy_names
    return (_get_coord_var_name(dataset, x_name, X_COORD_VAR_NAMES, 'x'),
  File "/home/users/tfincke/Projects/xcube/xcube/core/geocoding.py", line 447, in _get_coord_var_name
    raise ValueError(f'cannot detect {dim_name!r}-coordinate variable in dataset')
ValueError: cannot detect 'x'-coordinate variable in dataset
[2021-05-27 15:54:03] Request: 
open_dataset(ds_id=esacci.GHG.satellite-orbit-frequency.L2.CO2.TANSO-FTS.GOSAT.SRFP.v2-3-8.r1, store_id=cci-store, time_range=None, var_names=['surface_altitude_stdv', 'intensity_offset_o2a'], region=[-72.32182, -71.0534, -51.32182, -50.0534])

Traceback (most recent call last):
  File "test_cci_data_support.py", line 407, in test_open_ds
    dataset = open_dataset(ds_id=data_id,
  File "/home/users/tfincke/Projects/cate/cate/core/op.py", line 216, in __call__
    return_value = self._wrapped_op(**input_values)
  File "/home/users/tfincke/Projects/cate/cate/ops/io.py", line 85, in open_dataset
    ds, ds_id = cate.core.ds.open_dataset(dataset_id=ds_id,
  File "/home/users/tfincke/Projects/cate/cate/core/ds.py", line 438, in open_dataset
    dataset = select_subset(dataset, **subset_args)
  File "/home/users/tfincke/Projects/xcube/xcube/core/select.py", line 37, in select_subset
    dataset = select_spatial_subset(dataset, xy_bbox=bbox)
  File "/home/users/tfincke/Projects/xcube/xcube/core/select.py", line 86, in select_spatial_subset
    x_name, y_name = get_dataset_xy_names(dataset, xy_names=xy_names)
  File "/home/users/tfincke/Projects/xcube/xcube/core/geocoding.py", line 437, in get_dataset_xy_names
    return (_get_coord_var_name(dataset, x_name, X_COORD_VAR_NAMES, 'x'),
  File "/home/users/tfincke/Projects/xcube/xcube/core/geocoding.py", line 447, in _get_coord_var_name
    raise ValueError(f'cannot detect {dim_name!r}-coordinate variable in dataset')
ValueError: cannot detect 'x'-coordinate variable in dataset
[2021-05-27 16:22:33] Request: 
open_dataset(ds_id=esacci.GHG.satellite-orbit-frequency.L2.CO2.TANSO-FTS.GOSAT.SRFP.v2-3-8.r1, store_id=cci-store, time_range=None, var_names=['flag_landtype', 'xco2_quality_flag'], region=[46.41893, -81.04828, 67.41893, -60.04828])

Traceback (most recent call last):
  File "test_cci_data_support.py", line 410, in test_open_ds
    dataset = open_dataset(ds_id=data_id,
  File "/home/users/tfincke/Projects/cate/cate/core/op.py", line 216, in __call__
    return_value = self._wrapped_op(**input_values)
  File "/home/users/tfincke/Projects/cate/cate/ops/io.py", line 85, in open_dataset
    ds, ds_id = cate.core.ds.open_dataset(dataset_id=ds_id,
  File "/home/users/tfincke/Projects/cate/cate/core/ds.py", line 438, in open_dataset
    dataset = select_subset(dataset, **subset_args)
  File "/home/users/tfincke/Projects/xcube/xcube/core/select.py", line 37, in select_subset
    dataset = select_spatial_subset(dataset, xy_bbox=bbox)
  File "/home/users/tfincke/Projects/xcube/xcube/core/select.py", line 86, in select_spatial_subset
    x_name, y_name = get_dataset_xy_names(dataset, xy_names=xy_names)
  File "/home/users/tfincke/Projects/xcube/xcube/core/geocoding.py", line 437, in get_dataset_xy_names
    return (_get_coord_var_name(dataset, x_name, X_COORD_VAR_NAMES, 'x'),
  File "/home/users/tfincke/Projects/xcube/xcube/core/geocoding.py", line 447, in _get_coord_var_name
    raise ValueError(f'cannot detect {dim_name!r}-coordinate variable in dataset')
ValueError: cannot detect 'x'-coordinate variable in dataset
[2021-05-27 17:09:41] Request: 
open_dataset(ds_id=esacci.GHG.satellite-orbit-frequency.L2.CO2.TANSO-FTS.GOSAT.SRFP.v2-3-8.r1, store_id=cci-store, time_range=None, var_names=['exposure_id', 'chi2'], region=[-37.46822, 49.9303, -16.46822, 70.9303])

Traceback (most recent call last):
  File "test_cci_data_support.py", line 410, in test_open_ds
    dataset = open_dataset(ds_id=data_id,
  File "/home/users/tfincke/Projects/cate/cate/core/op.py", line 216, in __call__
    return_value = self._wrapped_op(**input_values)
  File "/home/users/tfincke/Projects/cate/cate/ops/io.py", line 85, in open_dataset
    ds, ds_id = cate.core.ds.open_dataset(dataset_id=ds_id,
  File "/home/users/tfincke/Projects/cate/cate/core/ds.py", line 438, in open_dataset
    dataset = select_subset(dataset, **subset_args)
  File "/home/users/tfincke/Projects/xcube/xcube/core/select.py", line 37, in select_subset
    dataset = select_spatial_subset(dataset, xy_bbox=bbox)
  File "/home/users/tfincke/Projects/xcube/xcube/core/select.py", line 86, in select_spatial_subset
    x_name, y_name = get_dataset_xy_names(dataset, xy_names=xy_names)
  File "/home/users/tfincke/Projects/xcube/xcube/core/geocoding.py", line 437, in get_dataset_xy_names
    return (_get_coord_var_name(dataset, x_name, X_COORD_VAR_NAMES, 'x'),
  File "/home/users/tfincke/Projects/xcube/xcube/core/geocoding.py", line 447, in _get_coord_var_name
    raise ValueError(f'cannot detect {dim_name!r}-coordinate variable in dataset')
ValueError: cannot detect 'x'-coordinate variable in dataset
