[2021-12-21 11:14:46] Request: 
open_dataset(ds_id=esacci.ICESHEETS.unspecified.Unspecified.IV.multi-sensor.multi-platform.UNSPECIFIED.1-1.greenland_timeseries_Zachariae_79Fjord, store_id=cci-store, time_range=None, var_names=['land_ice_surface_easting_velocity', 'land_ice_surface_easting_velocity'], region=[-73.89687, 64.6023, -71.89687, 66.6023])

Traceback (most recent call last):
  File "/home/xcube/projects/cate-e2e/testing-cci-datasets/test_cci_data_support.py", line 428, in test_open_ds
    dataset = open_dataset(ds_id=data_id,
  File "/home/xcube/projects/cate/cate/core/op.py", line 216, in __call__
    return_value = self._wrapped_op(**input_values)
  File "/home/xcube/projects/cate/cate/ops/io.py", line 85, in open_dataset
    ds, ds_id = cate.core.ds.open_dataset(dataset_id=ds_id,
  File "/home/xcube/projects/cate/cate/core/ds.py", line 452, in open_dataset
    dataset = select_subset(dataset, **subset_args)
  File "/home/xcube/miniconda3/envs/cate-env-development/lib/python3.9/site-packages/xcube/core/select.py", line 64, in select_subset
    dataset = select_spatial_subset(dataset, xy_bbox=bbox)
  File "/home/xcube/miniconda3/envs/cate-env-development/lib/python3.9/site-packages/xcube/core/select.py", line 131, in select_spatial_subset
    grid_mapping = GridMapping.from_dataset(dataset,
  File "/home/xcube/miniconda3/envs/cate-env-development/lib/python3.9/site-packages/xcube/core/gridmapping/base.py", line 664, in from_dataset
    return new_grid_mapping_from_dataset(
  File "/home/xcube/miniconda3/envs/cate-env-development/lib/python3.9/site-packages/xcube/core/gridmapping/dataset.py", line 103, in new_grid_mapping_from_dataset
    raise ValueError('cannot find any grid mapping in dataset')
ValueError: cannot find any grid mapping in dataset
