[2021-12-21 11:34:00] Request: 
open_dataset(ds_id=esacci.SEAICE.mon.L3C.SITHICK.RA-2.Envisat.NH25KMEASE2.2-0.r1, store_id=cci-store, time_range=None, var_names=['sea_ice_thickness_uncertainty', 'radar_freeboard_uncertainty'], region=[123.92603, 77.01338, 173.92603, 127.01338])

Traceback (most recent call last):
  File "/home/xcube/projects/cate-e2e/testing-cci-datasets/test_cci_data_support.py", line 428, in test_open_ds
    dataset = open_dataset(ds_id=data_id,
  File "/home/xcube/projects/cate/cate/core/op.py", line 216, in __call__
    return_value = self._wrapped_op(**input_values)
  File "/home/xcube/projects/cate/cate/ops/io.py", line 85, in open_dataset
    ds, ds_id = cate.core.ds.open_dataset(dataset_id=ds_id,
  File "/home/xcube/projects/cate/cate/core/ds.py", line 452, in open_dataset
    dataset = select_subset(dataset, **subset_args)
  File "/home/xcube/miniconda3/envs/cate-env-development/lib/python3.9/site-packages/xcube/core/select.py", line 64, in select_subset
    dataset = select_spatial_subset(dataset, xy_bbox=bbox)
  File "/home/xcube/miniconda3/envs/cate-env-development/lib/python3.9/site-packages/xcube/core/select.py", line 131, in select_spatial_subset
    grid_mapping = GridMapping.from_dataset(dataset,
  File "/home/xcube/miniconda3/envs/cate-env-development/lib/python3.9/site-packages/xcube/core/gridmapping/base.py", line 664, in from_dataset
    return new_grid_mapping_from_dataset(
  File "/home/xcube/miniconda3/envs/cate-env-development/lib/python3.9/site-packages/xcube/core/gridmapping/dataset.py", line 103, in new_grid_mapping_from_dataset
    raise ValueError('cannot find any grid mapping in dataset')
ValueError: cannot find any grid mapping in dataset
