[2021-06-15 10:58:09] Request: 
open_dataset(ds_id=esacci.SST.climatology.L4.SSTdepth.multi-sensor.multi-platform.OSTIA.2-1.r1, store_id=cci-store, time_range=('1982-01-01', '1982-02-01'), var_names=['mask', 'analysed_sst', 'sea_ice_fraction'], region=None)

Traceback (most recent call last):
  File "/home/tonio-bc/projects/ccitools/cate-e2e/testing-cci-datasets/test_cci_data_support.py", line 384, in test_open_ds
    force_local=False)
  File "/home/tonio-bc/projects/ccitools/cate/cate/core/op.py", line 216, in __call__
    return_value = self._wrapped_op(**input_values)
  File "/home/tonio-bc/projects/ccitools/cate/cate/ops/io.py", line 92, in open_dataset
    monitor=monitor)
  File "/home/tonio-bc/projects/ccitools/cate/cate/core/ds.py", line 456, in open_dataset
    dataset = data_store.open_data(data_id=dataset_id, opener_id=opener_id, **open_args)
  File "/home/tonio-bc/projects/dcs4cop/xcube-cci/xcube_cci/dataaccess.py", line 472, in open_data
    return self._get_opener(opener_id=opener_id).open_data(data_id, **open_params)
  File "/home/tonio-bc/projects/dcs4cop/xcube-cci/xcube_cci/dataaccess.py", line 245, in open_data
    chunk_store = CciChunkStore(self._cci_odp, data_id, cube_kwargs)
  File "/home/tonio-bc/projects/dcs4cop/xcube-cci/xcube_cci/chunkstore.py", line 664, in __init__
    trace_store_calls=trace_store_calls)
  File "/home/tonio-bc/projects/dcs4cop/xcube-cci/xcube_cci/chunkstore.py", line 83, in __init__
    raise ValueError('Could not determine any valid time stamps')
ValueError: Could not determine any valid time stamps
